Workbook

Sheet Laptop Replacement 2020
A1: SEB2020L | B1: 2020 | C1: 5CG014DTP7 | E1: HP Elitebook 840 G6 | F1: AC | G1: Andrew Chin | H1: ICT | I1: 17/11/2020 | J1: 17/11/2020 | K1: Replace NB | L1: Reallocate to CFS
A2: SEB2020L | B2: 0818 | C2: 5CG014DRQ2 | E2: HP Elitebook 840 G6 | F2: MFS | G2: Amalina Hilmy | H2: Credit Control | I2: 25/01/2021 | J2: 25/01/2021
A3: SEB2020L | B3: 0817 | C3: 5CG014DRPB | E3: HP Elitebook 840 G6 | F3: Art | G3: Irina Binti Azman Durai | H3: ICT | I3: 44442 | J3: 44472 | K3: Replacement
A4: SEB2020L | B4: 0816 | C4: 5CG014DTPP | E4: HP Elitebook 840 G6 | F4: AC | G4: Chong Hui Ching | H4: PD | I4: 44200 | J4: 44200 | K4: New joiner
A5: SEB2020L | B5: 0815 | C5: 5CG014DQCS | E5: HP Elitebook 840 G6 | F5: AC | G5: Junetta Manggie | H5: HR | I5: 44199 | J5: 44230 | K5: New
A6: SEB2020L | B6: 0814 | C6: 5CG014DRPV | E6: HP Elitebook 840 G6 | F6: Adam | G6: Tan Ming Wei | H6: Project Delivery | I6: 44230 | J6: 44258 | K6: New
A7: SEB2020L | B7: 0813 | C7: 5CG014DTQ7 | E7: HP Elitebook 840 G6 | F7: Art | G7: Alvin Lim Khiok Leong | H7: SER COO | I7: 23/02/2021 | J7: 44230 | K7: Temporary use | L7: Now permanent for Chai Tze Kong
A8: SEB2020L | B8: 0812 | C8: 5CG014DSMD | E8: HP Elitebook 840 G6 | F8: Adam | G8: Collin Tiong Inn Seng | H8: Distribution | I8: 22/2/2021 | J8: 44289 | K8: Replacement | L8: Replace HP 440 G2
A9: SEB2020L | B9: 0811 | C9: 5CG014DSY9 | E9: HP Elitebook 840 G6 | F9: Art | G9: William Ho Ming Chung | H9: PD | I9: 22/02/2021 | J9: 44289
A10: SEB2020L | B10: 0810 | C10: 5CG014DQNM | E10: HP Elitebook 840 G6 | F10: Adam | G10: Nur Azmina Binti Zainuddin | H10: Strategy & Corporate | I10: 13/2/2021 | J10: 44289 | K10: New
A11: SEB2020L | B11: 0809 | C11: 5CG014DRPG | E11: HP Elitebook 840 G6 | F11: Art | G11: Mohammed Faiz Julaihi | H11: Contract & Procurement | I11: 44471 | J11: 44289
A12: SEB2020L | B12: 0808 | C12: HCKDYX2 | E12: Dell Latitude 7424 | F12: JW | G12: Aniq | I12: 44230 | J12: 44230 | K12: Temporary swap
A13: SEB2020L | B13: 0807 | C13: 5GD045GBSH | E13: HP ZBook 15 G6 | F13: Adam | G13: Sharika A/P Kaliani | H13: Coal | I13: 44532 | J13: 18/2/2021 | K13: Replace Desktop | L13: Workstation with Workstation
A14: SEB2020L | B14: 0806 | C14: 5CG91673MC | E14: HP Elitebook 840 G6 | F14: MFS | G14: Jeffery Lai | H14: Wisma Sesco | I14: 44228 | K14: New Joiner
A15: SEB2020L | B15: 0805 | C15: 5CG014DT75 | E15: HP Elitebook 840 G6 | F15: Vendor | G15: Dygku Mimi Rosfarlina | H15: Sibu | I15: 44228 | J15: 44471 | K15: New Joiner
A16: SEB2020L | B16: 0804 | C16: 5CG014DT7X | E16: HP Elitebook 840 G6 | F16: YIP | G16: Davina Anak Eli | H16: SESCO Operational Excellence | I16: 29/01/2021 | J16: 44257 | K16: Replace Notebook | L16: Dell 3450
A17: SEB2020L | B17: 0803 | C17: 5CG014DQDS | E17: HP Elitebook 840 G6 | F17: Vendor | G17: Wong Chit Sing | H17: Sibu | I17: 29/01/2021 | K17: Replace Desktop PC
A18: SEB2020L | B18: 0802 | C18: 5CG014DTN8 | E18: HP Elitebook 840 G6 | F18: Vendor | G18: Leman Ak Aji | H18: Sibu | I18: 29/01/2021 | K18: Replace Desktop PC
A19: SEB2020L | B19: 0801 | C19: 5CG014DT8P | E19: HP Elitebook 840 G6 | F19: Vendor | G19: Abang Ismail B. Abang Daud | H19: Sibu | I19: 29/01/2021 | K19: Replace Desktop PC | L19: OSSM # S3784
A20: SEB2020L | B20: 0800 | C20: 5CG014DQQ2 | E20: HP Elitebook 840 G6 | F20: JW | G20: Muhammad Hanif | H20: Land & Wayleave | I20: 29/01/2021 | K20: New
A21: SEB2020L | B21: 0799 | C21: 5CG014DTN1 | E21: HP Elitebook 840 G6 | F21: JW | G21: Lee Yew Shien | H21: ICT | I21: 28/01/2021 | J21: 44198 | K21: New Joiner
A22: SEB2020L | B22: 0798 | C22: 5CG014DQF2 | E22: HP Elitebook 840 G6 | F22: AC | G22: Dayang Norsidah Binti Awang Rashid | H22: SEB Power | I22: 27/01/2021 | J22: 29/01/2021 | K22: Replace Noteobok | L22: Replacement on Stolen Unit sn: 5CG014DQDF
A23: SEB2020L | B23: 0797 | C23: 5CG0207MMX | E23: HP Elitebook 840 G6 | F23: Art | G23: Shazril Azizie Bin Zaidi | H23: Transmission | I23: 28/01/2021 | J23: 44471 | K23: Replace Desktop
A24: SEB2020L | B24: 0796 | C24: 5CG0207MNS | E24: HP Elitebook 840 G6 | F24: AC | G24: Kho Li Yen | H24: Retail (Sibu) | I24: 22/01/2021 | J24: 25/01/2021 | K24: Replace Desktop
A25: SEB2020L | B25: 0795 | C25: 5CG014DSXN | E25: HP Elitebook 840 G6 | F25: JW | G25: Liong Yiing Yang | H25: Retail (Sibu) | I25: 21/01/2021 | J25: 25/01/2021 | K25: Replace Desktop
A26: SEB2020L | B26: 0794 | C26: 5CG014DSY4 | E26: HP Elitebook 840 G6 | F26: Art | G26: Syamil Bin Ibrahim | H26: Distribution | I26: 21/01/2021 | J26: 25/01/2021
A27: SEB2020L | B27: 0793 | C27: 5CG014DQFF | E27: HP Elitebook 840 G6 | F27: YIP | G27: Hou Mee King | H27: Payment Bintulu | I27: 22/01/2021 | J27: 25/01/2021 | K27: Replace Desktop PC
A28: SEB2020L | B28: 0792 | C28: 5CG01472F6 | E28: HP ZBook 14 U G6 | F28: AC | G28: Kelvin Jee | H28: Strategy & Corporate | I28: 20/01/2021 | J28: 22/01/2021 | K28: Replace Notebook | L28: Replace Lenovo T470
A29: SEB2020L | B29: 0791 | C29: 5CD014DRMV | E29: HP Elitebook 840 G6 | F29: AC | G29: Andrew Lim Kheng Chuan | H29: Project Delivery | I29: 20/01/2021 | J29: 15/2/2021 | K29: New
A30: SEB2020L | B30: 0790 | C30: 5CG014DT7S | E30: HP Elitebook 840 G6 | F30: AC | G30: Simon Fowel Tami | H30: Generation Asset Management | I30: 28/06/2021 | J30: 44390 | K30: Replacement
A31: SEB2020L | B31: 0789 | C31: 5CG014DQDH | E31: HP Elitebook 840 G6 | F31: Adam | G31: lvis | H31: GCEO | I31: 16/1/2021 | J31: 18/01/2021 | K31: Replace Notebook
A32: SEB2020L | B32: 0788 | C32: 5CG014DQG2 | E32: HP Elitebook 840 G6 | F32: Art | G32: Fung Kwong Meng | H32: PD | I32: 14/01/2021 | J32: 15/02/2021
A33: SEB2020L | B33: 0787 | C33: 5CG014DSLZ | E33: HP Elitebook 840 G6 | F33: Adam | G33: Yii Yong Chong | H33: Distribution (Bintulu RO) | I33: 13/1/2021 | K33: New Joiner
A34: SEB2020L | B34: 0786 | C34: 5CG014DQD8 | E34: HP Elitebook 840 G6 | F34: AC | G34: Awang Hasnan Bin Awang Abdul Rahman | H34: IA | I34: 13/01/2021 | J34: 14/01/2021 | K34: Replace Noteobok | L34: Replace HP 440 G2
A35: SEB2020L | B35: 0785 | C35: 5CG014DQ1V | E35: HP Elitebook 840 G6 | F35: Art | G35: Anthony Wong Chiew Wu | H35: Finance | I35: 13/01/2021 | J35: 44198 | K35: New Joiner
A36: SEB2020L | B36: 0784 | C36: 5CG014DSLW | E36: HP Elitebook 840 G6 | F36: Adam | G36: Esther Moa Shu Qi | H36: PD | I36: 44531 | J36: 15/1/2021 | K36: New Joiner
A37: SEB2020L | B37: 0783 | C37: 5CG014DSLJ | E37: HP Elitebook 840 G6 | F37: Adam | G37: Mohamad Ardzuan Bin Aman | H37: Hydro | I37: 44501 | K37: Replace Desktop PC
A38: SEB2020L | B38: 0782 | C38: 5CG014DQ1K | E38: HP Elitebook 840 G6 | F38: Art | G38: Nur Amanina Binti Mohd Hanafi | H38: HSSE | I38: 44531 | J38: 22/03/2021
A39: SEB2020L | B39: 0781 | C39: 5CG014DRN8 | D39: Bitlocker | E39: HP Elitebook 840 G6 | F39: CFJ | G39: Chou Yeng Khai Liong Teck Hua | H39: ICT Operation | I39: 44501 | J39: 15/01/2021 | K39: New Joiner | M39: 5658710E-A0AB-472E-B569-058491D563B4 | N39: 398783-168421-010571-351538-075823-568711-554400-150337
A40: SEB2020L | B40: 0780 | C40: 5CG0207MNX | E40: HP Elitebook 840 G6 | F40: JW | G40: Tan Yong Siang | H40: Maintenance | I40: 44409 | J40: 44218 | K40: Replacement
...

Sheet Baleh HEP Assigned Computername
A1: Computer Name | C1: S/N | D1: Model | E1: Done by | F1: User Name | G1: Department | H1: Completed | I1: Date of Collection | J1: New / Replacement | K1: Returned Old Laptop / Desktop
A2: BLP2020L | B2: 0001 | C2: 5CG00920X8 | D2: HP Elitebook 840 G6 | E2: Adam | F2: Reuben Anak Jagai
A3: BLP2020L | B3: 0002 | C3: 5CG00920X2 | D3: HP Elitebook 840 G6 | E3: Adam | F3: Iliyana Kazulianie Binti Mansor
A4: BLP2020L | B4: 0003 | D4: HP Elitebook 840 G6
A5: BLP2020L | B5: 0004 | C5: 5CCG00920X9 | D5: HP Elitebook 840 G6 | E5: JW | F5: Dora Jau
A6: BLP2020L | B6: 0005 | C6: 5CG00906WF | D6: HP Elitebook 840 G6 i7 | E6: Art | F6: Kho Kiat Chai | G6: PD | H6: 17/03/2021 | I6: 44291 | J6: Replacement
A7: BLP2020L | B7: 0006 | C7: 5CG00920WW | D7: HP Elitebook 840 G6 | E7: Adam | F7: Paul Michael Raj | G7: PD | I7: 19-may-2021
A8: BLP2020L | B8: 0007 | C8: 5CG00920WV | D8: HP EB840 G6 (i7) | E8: ULH | F8: myvacseb | G8: Baleh HEP | H8: 16/06/2021 | I8: 18/06/2021 | J8: New
A9: BLP2020L | B9: 0008 | C9: 5CG00920X6 | D9: HP EB840 G6 (i7) | E9: ULH | F9: myvacseb | G9: Baleh HEP | H9: 16/06/2021 | I9: 18/06/2021 | J9: New
A10: BLP2020L | B10: 0009 | C10: 5CG00920WZ | D10: HP EB840 G6 (i7) | E10: ULH | F10: myvacseb | G10: Baleh HEP | H10: 16/06/2021 | I10: 18/06/2021 | J10: New
A11: BLP2020L | B11: 0010 | C11: 5CG00906WG | D11: HP EB840 G6 (i7) | E11: ULH | F11: myvacseb | G11: Baleh HEP | H11: 16/06/2021 | I11: 18/06/2021 | J11: New
A12: BLP2020L | B12: 0011 | D12: HP Elitebook 840 G6
A13: BLP2020L | B13: 0012 | D13: HP Elitebook 840 G6
A14: BLP2020L | B14: 0013 | C14: 5CG00906WP | D14: HP Elitebook 840 G6 | E14: Adam | F14: Irene Anak Deli
A15: BLP2020L | B15: 0014 | C15: 5CG00920X1 | D15: HP EB840 G6 (i7) | E15: ULH | F15: Rusydi Bin Raba'ie | G15: Baleh HEP | H15: 44115 | I15: 23/11/2020 | J15: New | K15: BLP2020L0001 change to 14
A16: BLP2020L | B16: 0015 | C16: 5CG00920X3 | D16: HP EB840 G6 (i7) | E16: ULH | F16: Sedah Anak Jagop | G16: Baleh HEP | H16: 23/11/2020 | I16: 43933 | J16: New | K16: BLP2020L0002 change to 15
A17: BLP2020L | B17: 0016 | C17: 5CG00920X0 | D17: HP EB840 G6 (i7) | E17: ULH | F17: Abdul Fazil bin Abdul Manan | G17: Baleh HEP | H17: 23/11/2020 | I17: 43933 | J17: New | K17: BLP2020L0003 change to 16
A18: BLP2020L | B18: 0017 | C18: 5CG00906WK | D18: HP EB840 G6 (i7) | E18: ULH | F18: Daniel anak Abel | G18: Baleh HEP | H18: 23/11/2020 | I18: 43933 | J18: New | K18: BLP2020L0004 change to 17
A19: BLP2020L | B19: 0018 | C19: 5CG00920WS | D19: HP EB840 G6 (i7) | E19: ULH | F19: Timothy Hii Lu Cherng | G19: Baleh HEP | H19: 44348 | I19: 44230 | J19: New | K19: BLP2020L0005 change to 18
A20: BLP2020L | B20: 0019 | C20: 5CG00906WM | D20: HP EB840 G6 (i7) | E20: ULH | F20: Kemmy anak John | G20: Baleh HEP | H20: 24/02/2021 | I20: 44230 | J20: New | K20: BLP2020L0006 change to 19
A21: BLP2020L | B21: 0020 | C21: 5CG00920WR | D21: HP EB840 G6 (i7) | F21: Rumpang Anak Usat@Gumbang | G21: Baleh HEP | K21: Ex-Catherine Encharang
A23: BLP2021L | B23: 0001 | C23: 5CG00920XB | D23: HP EB840 G6 (i7) | E23: ULH | F23: Alex anak Ladi | G23: Baleh HEP | H23: 28/07/2021 | I23: 44538 | J23: New
A24: BLP2021L | B24: 0002 | C24: 5CG00920WP | D24: HP EB840 G6 (i7) | E24: ULH | F24: Nichard anak Nichol | G24: Baleh HEP | H24: 44538 | I24: 44531 | J24: New
A25: BLP2021L | B25: 0003 | C25: 5CG00920XC | D25: HP EB840 G6 (i7) | E25: ULH | F25: Thomas Chin Jun Yen | G25: Baleh HEP | H25: 11/26/2021 | I25: 44529 | J25: New
A26: BLP2021L | B26: 0004 | C26: 5CG00920X7 | D26: HP EB840 G6 (i7) | E26: ULH | F26: Anthony Njok Balan | G26: Baleh HEP | H26: 44705 | I26: 44719 | J26: New
A27: BLP2021L | B27: 0005 | C27: Reserve | D27: HP EB840 G6 (i7) | E27: ULH | G27: Baleh HEP | J27: New
A28: BLP2021L | B28: 0006 | C28: 5CG00920X4 | D28: HP EB840 G6 (i7) | E28: JWPJ | F28: Bong Chien Chai | G28: Baleh HEP | H28: 44419 | I28: 44440 | J28: New | K28: User resigned - Laptop returned on 25/1/2022 | L28: Re-assign to Jonathan.
A29: BLP2021L | B29: 0007 | C29: 5CG00906WH | D29: HP EB840 G6 (i7) | E29: Arth | F29: Jaynsen Anak Patrick Sibat | G29: Baleh HEP | H29: 12-Oct-2021 | J29: New | K29: S11290
A30: BLP2021L | B30: 0008 | C30: 5CG00906WD | D30: HP EB840 G6 (i7) | F30: Lim Chew Hin | G30: Baleh HEP | I30: 03-Jan-2022 | J30: New Joiner | K30: Received @HQ 14-Oct-2021
A31: BLP2021L | B31: 0009 | C31: 5CG00920WT | D31: HP EB840 G6 (i7) | E31: Adam | F31: Nayli Batrisyia Binti Nordin | G31: Baleh HEP | J31: New Joiner | K31: Received @HQ 14-Oct-2021
A32: BLP2021L | B32: 0010 | C32: 5CG00920WY | D32: HP EB840 G6 (i7) | E32: Adam | F32: Alexson Sangau Anak John | G32: Baleh HEP | H32: 44805 | J32: New Joiner | K32: Received @HQ 14-Oct-2021 | L32: OSSM # S20590
A33: BLP2021L | B33: 0011 | C33: 5CG00920WQ | D33: HP EB840 G6 (i7) | E33: Adam | F33: Fatin Syazwin Bt. Sukor | G33: Baleh HEP | J33: New Joiner | K33: Received @HQ 14-Oct-2021 | L33: OSSM # S20656

Sheet NOT BY ICT
B1: Computers that were not purchased by ICT
B2: Joined to Domain with approval
B4: Computer Name | C4: Serial Number | D4: Brand/Model | E4: Username | F4: Location | G4: Dept/Division | H4: Requestor | I4: OSSM Ticket Number
B5: SE2023TCCBTU001 | C5: D37502BH80224 | E5: BINRDC | F5: Bintulu TCC Display Signage | G5: TCC | H5: Desmond Ong/Clashovic | I5: S24301
B6: SE2023TCCBTU002 | C6: D37502BH80665 | E6: BINRDC | F6: Bintulu TCC Display Signage | G6: TCC | H6: Desmond Ong/Clashovic | I6: S24301
B7: SE2023TCCMIR003 | C7: D37502GH10619 | E7: MIRRDC | F7: MINI PC for Miri TCC Display Signage | G7: TCC | H7: Desmond Ong/Chen Foo Yowi | I7: S24264

Sheet Reassigned Laptops_PC
B1: Returned Laptops/Desktop for re-assign
B3: Assign Date | C3: Computer Name | D3: Serial No. | E3: For User | F3: Dept/Div | G3: Requester | H3: OSSM # | I3: Previous User | J3: New requester contract period | K3: C.C. | L3: Completed | M3: Identifier | N3: Recovery Key
C4: SEB10L6846 | D4: 5CG916730F | E4: QKAFFADZEL ZHARFAN BIN KAMAL - | F4: Wayleave Consultant | G4: Muhammad Hanif Bin Morshidi | H4: S13765 | J4: Work contract : 3 Jan 2022 till 2 Jan 2024
C5: SEB01L4809 | D5: 8WK0QN2 | E5: Catherine Pua Mei Ling - | F5: Wayleave Consultant | G5: Muhammad Hanif Bin Morshidi | H5: S13766 | I5: Ex-Goh Lee Hoon | J5: Work contract : 3 Jan 2022 till 2 Jan 2024
C6: SEB10L6898 | D6: 5CG91630G5 | E6: Aiman Bin Alfian - | F6: Wayleave Consultant | G6: Muhammad Hanif Bin Morshidi | H6: S13764 | I6: Ex-Muhammad Nur Khairi | J6: Work contract : 3 Jan 2022 till 2 Jan 2024
C7: SEB2020L0538 | D7: 5CG014DSX8 | E7: ICT Tender SEUser01 | I7: Bunyak Lunyong | J7: Bunyak assigned with HP X360 G7
B9: 44889 | C9: SEB2021L1097 | D9: 5CG1419M7Z | E9: Nurshafeena Binti Zainal Abidin | F9: PDD Consultant, Electrical Engineering | G9: Elysha Anak Woa | H9: S23491 | I9: Ex-Winston Ling | J9: Contract from 03-Jan-2023 - 24 months
B10: 44889 | C10: SEB2022L0815 | D10: 5CG1419M13 | E10: Lucy Saroja Daui Michael Thilleveran | F10: GCEO Office | G10: -- | I10: Ex-Luk Ing Ping | J10: Replace Lucy's Dell 7490 SEB10L5431
B11: 44929 | C11: SEB2020L0752 | D11: 5CG0207MN1 | E11: Liew Swee Chen | F11: Distribution - Maintenance, KRO | G11: -- | H11: S24589 | I11: Ex-Chang Lee Ling
B12: 44929 | C12: SEB2021L0844 | D12: 5CG1032VBS | E12: Mohd Faizal Bin Sarkawi | F12: Distribution - Maintenance, KRO | G12: -- | H12: S24188 | I12: Ex-Alex Lai
B13: 44932 | C13: SEB10D5660 | D13: 4CE9091TZW | E13: Taqiuddin Bin Ahmad Kendong | F13: HSSE - Centre of Excellence | G13: Taqiuddin Bin Ahmad Kendong | H13: S24937 | I13: Ex-Annie Sim Pei Tsu | J13: ACS at Menara Sarawak Energy.
E14: Taqiuddin Bin Ahmad Kendong | F14: HSSE - Centre of Excellence | G14: Taqiuddin Bin Ahmad Kendong | H14: S24946 | J14: ACS at Wisma SESCO.
E15: Taqiuddin Bin Ahmad Kendong | F15: HSSE - Centre of Excellence | G15: Taqiuddin Bin Ahmad Kendong | H15: S24945 | J15: ACS at Kuching Regional Office.
B16: 44936 | C16: SEB2021L0621 | D16: 5CG1036D2J | E16: Valery Lirang Laing - CFS | F16: Project Delivery - Office Support | G16: Nur Yasmin Binti Abdul Halim | H16: S25066 | I16: Ex-Stephanie Chin | J16: 44928 | K16: S25066 | L16: 20-Jan-2023
B17: 44936 | C17: SEB2021L1048 | D17: 5CG1117Q9V | E17: Deckie Anak Lawai - CFS | F17: Project Delivery - Office Support | G17: Nur Yasmin Binti Abdul Halim | H17: S25068 | I17: Ex-Ann-Marie Tan Wei Ping | J17: 44928 | K17: 710123
B18: 44938 | C18: SEB10L5949 | D18: 5CG9167C12 | E18: JULIUS ANAK WILLIAM DEE - CFS | F18: R&D Environmental Sciences | G18: Luk Ing Ping | H18: S25232 | I18: Ex-Huong Yuli | J18: 02-Jan-2023 to 31-Jan-2025 | K18: 510103 | L18: 17-Jan-2023
B19: 44938 | C19: SEB2021L1020 | D19: 5CG1032VQX | E19: Awang Seiful Bahari bin Awang Shawal | F19: Distribution - Warehouse Management | G19: Charles Ak Fidelis Batest | H19: S25219 | I19: Ex- Angelo Emanuel Robin | J19: Awangh Seiful - Shared Dekstop PC user. | K19: 510146
B20: 44938 | C20: SEB2021L0303 | D20: 5CG1036B5B | E20: Chan Kit Hie | F20: Project Delivery - Quality Assurance & Quality Controls | G20: Matthias Michel Peter | H20: S25264 | I20: Jackie Amar | J20: 1-Feb-2023 to 31-Jan-2025 | K20: 710124
B21: 44957 | C21: SEB2021L1089 | D21: 5CG1432GTN | E21: Tan Chuan Ngan | F21: Hydro - Office Support | G21: Ting Li Cheng | H21: S25741 | I21: Tan Chuan Ngan | J21: CFS w.e.f. 01-Feb-2023 | K21: 110105
B22: 44963 | C22: SEB2021L0459 | D22: 5CG1036GRZ | E22: Esther Anak Andrew Mapi | F22: Corporate Services | G22: Esther Anak Andrew Mapi | H22: S25970 | I22: Amanda Lee Hsiao Ling | J22: Re-assigned to Esther. | K22: 510169 | L22: 23-Mar-2023
B23: 44966 | C23: SEB2021L1243 | D23: 5CG1432J47 | E23: Tan Boon Hui | F23: Contract & Procurement - Capital Works | G23: Lim Lee Chin | H23: S26025 | I23: Kho Chung Ho | J23: Re-assigned to Tan Boon Hui | K23: 710122 | L23: 17-Feb-2023
C24: SEB2021L1275 | D24: 5CG1432G45 | I24: Hetty Munira
B25: 44965 | C25: SEB2020L0518 | D25: 5CG014DQ1L | E25: Justine Pengiran ak Igai | F25: ICT | G25: Elizabeth Kueh | H25: S25895 | I25: Tan Cho Yian | J25: CFS w.e.f. 01-Mar-2023 | K25: 610114
B26: 44972 | C26: SEB2021L1504 | D26: CND12345CC | E26: Shitian Ling | F26: Strategy & Corporate Development | G26: -- | I26: Jonny Wong (Bakun) | J26: Replace 5CG9167BQ4 HP 840 G5 | L26: 15-Feb-2023
I27: Naday Kalem
I28: Lily Henry
B29: 44998 | C29: SEB2021L1132 | D29: 5CG1432GTQ | E29: Afi Bazilah Binti Abu | F29: Project Delivery | G29: Nurul Yasmin Binti Abdul Halim | H29: S27405 | I29: Muhammad Saifuddin Bin Bakri | J29: CFS w.e.f 03-April-2023 | K29: 710123 | L29: 23-Mar-2023
B30: 45007 | C30: SEB2021L1374 | D30: 5CG1432GKC | E30: Siti Aishah Binti Abdullah | F30: Project Delivery | G30: Anatasha Anak Johnnes Gobli | H30: S27584 | I30: Mohd Shuffy Bin Suhaidi | J30: CFS w.e.f 01-May-2023 | K30: 710121
C31: SEB2021L1517 | D31: 5CG1432HJO | I31: Dennis Chee Jun Sheng
B32: 45121 | C32: SEB2021L1808 | D32: 5CG1432HGK | E32: Aliff Adafi Bin mahmud | F32: HR | G32: Kimberley Ak Engkamat | H32: S31341 | I32: Yong Hua Keh | J32: Intern w.e.f. 31-July-2023. | K32: 510168
B33: 45121 | C33: SEB2021L1005 | D33: 5CG1032VHN | E33: Andrea Jane Ak Intai | F33: HR | G33: Kimberley Ak Engkamat | H33: S31348 | I33: Hafizam Bin Zamani | J33: Intern w.e.f. 31-July-2023. | K33: 510168
B34: 45152 | C34: SEB2020L0792 | D34: 5CG01472F6 | E34: Jimmy Ling/Gary Royston | F34: Transmission - Electrical Works | G34: Gary Royston | H34: S31127 | I34: Kelvin Jee Yap Yin | J34: For software testing | K34: 210103
C35: SEB10L5877 | D35: 5CG9123MLM | I35: Aveline Wong
C36: SEB10L4338 | D36: 5CG740304P | I36: Robin Kueh Kay Heng
C37: SEB01L6306 | D37: 5CG91673S4 | I37: Arfindy Ak Tajan
B38: 45127 | C38: SEB2023L2512 | D38: 5CG21631Z6 | E38: Chin Soon Ted | F38: HSSE - Occupational Safety | G38: Chin Soon Ted | H38: S31541 | I38: Elizabeth Lim Ya Wen
C39: SEB2022L2333 | D39: 5CG21631BS | E39: Chai Chiaw Wei | F39: CPG | I39: Ong Sie Siong
B40: 45141 | C40: SEB2022L2152 | D40: 5CG21630HG | E40: Willi Anak Miruk | F40: ICT - Data Center Management | G40: Kartina Wong Chin Ping | H40: S31775 | I40: Kenny Kueh Yung Shin
B41: 45166 | C41: SEB06D7270 | D41: 4CE9140KR3 | E41: Anbrey Law Buong Shyuan | F41: ICT - Data Center Management | G41: Anbrey Law Buong Shyuan | H41: S32578 | I41: Dyg Euis Julianti Bt Awang Mustfa | K41: 610108
B42: 45366 | C42: SEB2022L2038 | D42: 5CG216322T | E42: Deborah Anak Amit - CFS | F42: ICT - Infra | G42: Lee Yih Siew | H42: S40510 | I42: Leonora Liong Peh Ling | J42: 1 April 2024 - 31 March 2026 | L42: 15-Mar-2024
...

Sheet Test-Replacement
B1: Laptop Replaced | C1: Serial # | D1: Model | E1: Loan | F1: Remarks
A2: NB >> NB | B2: SEB10L7196 | C2: 5CD9450R8H | D2: HP EliteBook x360 1030 G4
A3: DT >> NB | F3: Shared Desktop PC user.
A4: NB >> NB | B4: SEB10L3620 | C4: 6645YB2 | D4: Dell Latitude 3470
A5: DT >> NB | F5: Shared Desktop PC user.
A6: DT >> NB | F6: Shared Desktop PC user.
A7: NB >> NB | B7: SEB10L3092 | C7: CND5247SC7 | D7: HP ProBook 440 G2
A8: NB >> NB | B8: SEB10L5281 | C8: F82YPN2 | D8: Dell Latitude 7490
A9: NB >> NB | B9: SEB10L3749 | C9: 2M15YB2 | D9: Dell Latitude 3470
A10: DT >> NB | F10: Shared computer user.
A11: NB >> NB | B11: SEB10L4714 | C11: JR9RPN2 | D11: Dell Latitude 7490
A12: NB >> NB | B12: SEB10L4848 | C12: 7Q1SPN2 | D12: Dell Latitude 7490
A13: DT >> NB | F13: Shared Desktop PC user.
A14: NB >> NB | B14: SEB10L5064 | C14: PF0VM90T | D14: Lenovo T470
A15: NB >> NB | B15: SEB2020L0381 | C15: 5CG014DSW2 | D15: HP EliteBook 840 G6
A16: NB >> NB | B16: SEB10L4602 | C16: FMGYZM2 | D16: Dell Precision 5520
A17: NB >> NB | B17: SEB10L4876 | C17: 81L0QN2 | D17: Dell Latitude 7490
A18: NB >> NB | B18: SEB10L4653 | C18: 76QCZM2 | D18: Dell Latitude 7480
A19: DT >> NB | F19: Shared Desktop PC user (SPC)
A20: DT >> NB | F20: Shared Desktop PC user previously.
A21: NB >> NB | B21: SEB10L4913 | C21: BXNRPN2 | D21: Dell Latitude 7490
A22: NB >> NB | B22: SEB10L4342 | C22: 5CG740301X | D22: HP EliteBook 840 G4
A23: DT >> NB | B23: SEB00D5708 | C23: 4CE909216B | D23: Desktop PC
A24: DT >> NB | B24: SEB00D5684 | C24: 4CE9092176 | D24: HP EliteDesk 800 G4
A25: NB >> NB | B25: SEB10L4194 | C25: 5CG74030K4 | D25: HP EliteBook 840 G4
A26: NB >> NB
A27: NB >> NB
A28: NB >> NB | B28: SEB10L4840 | C28: JZVRPN2 | D28: Dell Latitude 7490
A29: NB >> NB | B29: SEB10L5206 | C29: CDKQPN2 | D29: Dell Latitude 7490
A30: DT >> DT | B30: SEB10D3561 | C30: SGH634STX7 | D30: HP Z640
A31: DT >> NB
A32: DT >> NB
A33: DT >> NB
A34: NB >> NB | B34: SEB10L5446 | C34: 97JSPN2 | D34: Dell Latitude 7490
A35: NB >> NB | B35: SEB10L4603 | C35: BDGYZM2 | D35: Dell Precision 5520
A36: DT >> DT
A37: DT >> NB
A38: NB >> NB | B38: SEB10L4799 | C38: 76HRPN2 | D38: Dell Latitude 7490
A39: NB >> NB | B39: SEB2021L1555 | C39: 5CG1432FNT | D39: HP EliteBook 840 G7
A40: NB >> NB | B40: SEB10L4847 | C40: 5C1SPN2 | D40: Dell Latitude 7490
...

Sheet Sheet2
A1: Date | B1: User name
A2: 01-Dec-2021 | B2: Zaidi Minggu
A3: 01-Dec-2021 | B3: Slyvester Chendang Anak Seman
A4: 01-Dec-2021 | B4: Mohamad Yusuf Tan Abdullah
A5: 02-DEC-2021 | B5: Nur Iqmal Bin Khirudin
A6: 06-Dec-2021 | B6: Anne Sabine Ak Pamap
A7: 07-Dec-2021 | B7: Wong Ing Siong
A8: 08-Dec-2021 | B8: George Harrison Lee Anak Joblee
A9: 08-Dec-2021 | B9: Mohamad Khairul Sarini Bin Bujang
A10: 09-Dec-2021 | B10: Peter Alphonso
A11: 09-Dec-2021 | B11: Gabriel Robson Anak Muton
A12: 09-Dec-2021 | B12: Azra Arina binti Zainurin
... A39: 14-Dec-2021 | B39: LIM CHEW HIN
A40: 44501 | B40: NUR AINIZA BINTI ZAKARIA
A41: 44501 | B41: Carlos Fong Vun Poh
A42: 44501 | B42: Marini Bte Merikan
A43: 44501 | B43: Wilson Juan Anak Baie
A44: 44501 | B44: Nelson Ak Mangkau
A45: 44501 | B45: Rimond Ijau Anak Bata
A46: 44501 | B46: Mohammad Salahuddin Bin Abu Bakar
A47: 44501 | B47: Edward Bin Bernabas Semait
A48: 44501 | B48: Lim Shu Lip
A49: 44501 | B49: Navin Iswandi Bin Bujang
A50: 44501 | B50: Yazid Bin Yakup
A51: 44503 | B51: Husni Diyana Binti Sarbini
... A101: 44530 | B101: Aimi Binti Zainuddin
B103: Dennis Harun ?
A105: CFS
A106: 44516 | B106: Cindy Sylvia Binti Albert Merican
A107: 44516 | B107: Thomas Chin Jun Yen
A108: 30-09-2021 | B108: Mohd. Endi Joni
A109: 04-Oct-2021 | B109: Abdul Mannaff bin Alias
A110: 05-Oct-2021 | B110: Lorderizk Nawang Simon
A111: 05-Oct-2021 | B111: JESSICA EMPANG LIAN
A112: 05-Oct-2021 | B112: Anne Eliza Anak Dolim
A113: 05-Oct-2021 | B113: DELLA ANAK RAMBA
A114: 05-Oct-2021 | B114: Albert Chew Kwang Heng
A115: 05-Oct-2021 | B115: Lee Tian Sang
A116: 05-Oct-2021 | B116: Benard Chen
A117: 07-Oct-2021 | B117: Danesh Mailvaganam
...

Sheet 2021 NEW
A1: Computer Name | C1: S/N | D1: Encryption | E1: Model | F1: Assign To | G1: User Name | H1: Department | I1: S | J1: Section/Division | L1: Completed | M1: Date Laptop Assigned | N1: New/Adhoc/Replace | O1: Month Requested | P1: Ticket No. | Q1: Remarks | R1: Identifier | S1: Recovery Key
A2: SEB2021L | B2: 0001 | C2: 5CG1036DRR | D2: y | E2: HP EliteBook 840 G7 | F2: Aziz | G2: Mohd. Zulhazis Bin Brahim | H2: Distribution | J2: Dalat | K2: Sibu | L2: 19/04/2021 | M2: 21/04/2021 | O2: =_xlfn.XLOOKUP(G2,Sheet2!B:B,Sheet2!A:A,"",0,1) | P2: Reserved for vendor servcies
A3: SEB2021L | B3: 0002 | C3: 5CG1036C1K | D3: Y | E3: HP EliteBook 840 G7 | F3: Yip | G3: Julian Ak Peter | H3: Retail | K3: Wisma | L3: 31-Mar-2021 | M3: 31-Mar-2021 | N3: DT >> NB | O3: =_xlfn.XLOOKUP(G3,Sheet2!B:B,Sheet2!A:A,"",0,1) | P3: "
A4: SEB2021L | B4: 0003 | C4: 5CG1036DCY | D4: Bitlocker | E4: HP EliteBook 840 G7 | F4: MHZ | G4: Stephenie Alvina Dadi | H4: Distribution | J4: Operational Excellence | K4: Bintulu | L4: 44443 | M4: 44443 | N4: DT >> NB | O4: =_xlfn.XLOOKUP(G4,Sheet2!B:B,Sheet2!A:A,"",0,1) -> 44271 | P4: " | R4: 36011E62-BC25-448C-8153-2DE22CAEF61A | S4: 344267-622006-060654-581955-334928-070840-557645-338261
A5: SEB2021L | B5: 0004 | C5: 5CG1036F5B | D5: Y | E5: HP EliteBook 840 G7 | F5: Yip | G5: Kho Li Fang | H5: Retail | K5: Wisma | L5: 31-Mar-2021 | M5: 31-Mar2021 | N5: DT >> NB | O5: =_xlfn.XLOOKUP(G5,Sheet2!B:B,Sheet2!A:A,"",0,1) | P5: "
A6: SEB2021L | B6: 0005 | C6: 5CG1032VFG | E6: HP EliteBook 840 G7 | F6: AC | G6: Eunice Chai Yuan Shiun | K6: Menara | L6: 19-Mar-2021 | M6: 17-May-2021 | N6: New Request | O6: =_xlfn.XLOOKUP(G6,Sheet2!B:B,Sheet2!A:A,"",0,1) -> 44270 | P6: " | R6: DT >> DT
A7: SEB2021L | B7: 0006 | C7: 5CG1036B4Z | D7: Bitlocker | E7: HP EliteBook 840 G7 | F7: Art | G7: Muhammad Nur Aiman Bin Ibrahim Lionel Leo Renggie Anak Michael Luncha | H7: PDD Contract & Procurement - Capital Works | I7: 710122 | J7: Contract & Procurement - Capital Works | K7: Sibu | L7: 6-Apr-2021 | M7: 20-Apr-2021 | O7: =_xlfn.XLOOKUP(G7,Sheet2!B:B,Sheet2!A:A,"",0,1) | P7: S51531 | R7: DT >> NB
A8: SEB2021L | B8: 0007 | C8: 5CG1036GF7 | D8: y | E8: HP EliteBook 840 G7 | F8: AC | G8: Ulok Kalang | H8: SPC | K8: SPC | L8: 29-Mar-2021 | M8: 06-Apr-2021 | N8: NB >> NB | O8: =_xlfn.XLOOKUP(G8,Sheet2!B:B,Sheet2!A:A,"",0,1) -> 44270 | P8: " | R8: NB >> NB
A9: SEB2021L | B9: 0008 | C9: 5CG1036F4L | E9: HP EliteBook 840 G7 | G9: Muhammad Tarmizi Bin Abdul Hamid | H9: SEB Power | K9: Menara | M9: 17-Aug-2021 | O9: =_xlfn.XLOOKUP(G9,Sheet2!B:B,Sheet2!A:A,"",0,1) -> 44272 | P9: " | R9: New Joiner
A10: SEB2021L | B10: 0009 | C10: 5CG1036C1J | D10: y | E10: HP EliteBook 840 G7 | F10: Aziz | G10: Yap Kuok Chiang | H10: Mukah - Petian | K10: Mukah | L10: 19/04/2021 | M10: 21/04/2021 | O10: =_xlfn.XLOOKUP(G10,Sheet2!B:B,Sheet2!A:A,"",0,1) | P10: " | R10: New Request
A11: SEB2021L | B11: 0010 | C11: 5CG1036D3B | D11: y | E11: HP EliteBook 840 G7 | F11: Aziz | G11: Affendy Bin Nawi | H11: Distribution | K11: Dalat | L11: 19/04/2021 | M11: 21/04/2021 | O11: =_xlfn.XLOOKUP(G11,Sheet2!B:B,Sheet2!A:A,"",0,1) | P11: "
A12: SEB2021L | B12: 0011 | C12: 5CG1036HDY | D12: Bitlocker | E12: HP EliteBook 840 G7 | F12: MHZ | G12: Amirah Binti Zaidel | J12: Operational Excellence | K12: Bintulu | L12: 44443 | M12: 44443 | N12: DT >> NB | O12: =_xlfn.XLOOKUP(G12,Sheet2!B:B,Sheet2!A:A,"",0,1) -> 44271 | P12: " | R12: DB27C95D-323C-4D23-A80C-61CA740465AA | S12: 698346-601117-009240-528946-498531-237490-688083-461967
A13: SEB2021L | B13: 0012 | C13: 5CG1036GFP | D13: y | E13: HP EliteBook 840 G7 | F13: Aziz | G13: Mohamad Jamalludin Bin Arsat | H13: Mukah - Petian | K13: Mukah | L13: 20/04/2021 | M13: 22/04/2021 | O13: =_xlfn.XLOOKUP(G13,Sheet2!B:B,Sheet2!A:A,"",0,1) | P13: "
A14: SEB2021L | B14: 0013 | C14: 5CG1036BV1 | D14: Y | E14: HP EliteBook 840 G7 | F14: MHZ | G14: Boon Koh Zack | H14: Store - Bintulu Power Station | K14: Bintulu | L14: 16/04/2021 | M14: 16/04/2021 | O14: =_xlfn.XLOOKUP(G14,Sheet2!B:B,Sheet2!A:A,"",0,1) | P14: " | R14: Kuching
A15: SEB2021L | B15: 0014 | C15: 5CG1036BV2 | D15: Y | E15: HP EliteBook 840 G7 | F15: MHZ | G15: Clayvian Anak Joshua | H15: Store - Bintulu Power Station | K15: Bintulu | L15: 16/04/2021 | M15: 16/04/2021 | O15: =_xlfn.XLOOKUP(G15,Sheet2!B:B,Sheet2!A:A,"",0,1) | P15: " | R15: Sibu
A16: SEB2021L | B16: 0015 | C16: 5CG1036GF4 | D16: Bitlocker | E16: HP EliteBook 840 G7 | F16: MHZ | G16: Victor Nyagang Wong King Kai | H16: Mechanical - Bintulu Power Station | K16: Bintulu | L16: 16/04/2021 | M16: 16/04/2021 | N16: DT >> NB | O16: =_xlfn.XLOOKUP(G16,Sheet2!B:B,Sheet2!A:A,"",0,1) | P16: " | R16: Miri | T16: 6FFE9611-4767-47C7-A421-0A62E961FA35 (Identifier)
A17: SEB2021L | B17: 0016 | C17: 5CG1036C8Z | D17: Bitlocker | E17: HP EliteBook 840 G7 | F17: Fairul | G17: Molis Alissong Anak Noyeng | H17: RMD | K17: Wisma SESCO | L17: 20-Apr-2021 | M17: 22-Apr-2021 | N17: NB >> NB | O17: =_xlfn.XLOOKUP(G17,Sheet2!B:B,Sheet2!A:A,"",0,1) -> 44272 | P17: S3673 | R17: Sri Aman
A18: SEB2021L | B18: 0017 | C18: 5CG1036GRD | D18: y | E18: HP EliteBook 840 G7 | F18: Aziz | G18: Norman Bin James Spawi | H18: Distribution | K18: Dalat | M18: 21/04/2021 | O18: =_xlfn.XLOOKUP(G18,Sheet2!B:B,Sheet2!A:A,"",0,1) -> 44274 | P18: " | R18: Sarikei
A19: SEB2021L | B19: 0018 | C19: 5CG1036F4H | E19: HP EliteBook 840 G7 | F19: Adam | G19: Marissa Binti Edwin Yassin Abdullah | H19: Contract Procurement & Governance | K19: Kuching | L19: 29-Mar-2021 | M19: 01-April-2021 | O19: =_xlfn.XLOOKUP(G19,Sheet2!B:B,Sheet2!A:A,"",0,1) -> 44271 | P19: " | R19: Bintulu
A20: SEB2021L | B20: 0019 | C20: 5CG1036DST | D20: Y | E20: HP EliteBook 840 G7 | F20: Aziz | G20: Norhalek Bin Mohd Syaifol @ Atek | H20: Mukah - Petian | K20: Mukah | L20: 19/04/2021 | M20: 22/04/2021 | O20: =_xlfn.XLOOKUP(G20,Sheet2!B:B,Sheet2!A:A,"",0,1) | P20: "
A21: SEB2021L | B21: 0020 | C21: 5CG1036DRT | D21: Bitlocker | E21: HP EliteBook 840 G7 | F21: ULH | G21: Jenifer Jakub | H21: Distribution | K21: Sibu | L21: 19/04/2021 | M21: 21/04/2021 | O21: =_xlfn.XLOOKUP(G21,Sheet2!B:B,Sheet2!A:A,"",0,1) -> 44273 | P21: " | R21: 2D5EEDD8-D4CD-4AAB-8572-04BE40E8E6FC | S21: 247236-072490-098868-100529-495363-487201-626945-169994
A22: SEB2021L | B22: 0021 | C22: 5CG1036B4W | D22: Bitlocker | E22: HP EliteBook 840 G7 | F22: JW | G22: Yong Jin Cheok | H22: Transmission | K22: Menara | L22: 29/03/2021 | M22: 44347 | N22: NB >> NB | O22: =_xlfn.XLOOKUP(G22,Sheet2!B:B,Sheet2!A:A,"",0,1) | P22: " | R22: 96785E28-0F0B-4F9A-872D-BEFB19CB17EE | S22: 543235-301136-327833-216513-086944-432542-128524-135960
A23: SEB2021L | B23: 0022 | C23: 5CG1036GFC | D23: Y | E23: HP EliteBook 840 G7 | F23: AC | G23: Charles Gregory Anak Kipo | H23: Transmission | K23: Menara | L23: 29-Mar-2021 | M23: 03-May-2021 | N23: NB >> NB | O23: =_xlfn.XLOOKUP(G23,Sheet2!B:B,Sheet2!A:A,"",0,1) | P23: "
A24: SEB2021L | B24: 0023 | C24: 5CG1036GZ8 | D24: Bitlocker | E24: HP EliteBook 840 G7 | F24: JW | G24: Mohamad Tajuddin Bin Mohd Nazir | H24: Transmission | K24: Menara | L24: 29/03/2021 | M24: 44351 | N24: NB >> NB | O24: =_xlfn.XLOOKUP(G24,Sheet2!B:B,Sheet2!A:A,"",0,1) | P24: " | R24: E81A49CA-73DF-4083-BE8E-D5C2DF102809 | S24: 410784-044946-381403-330121-708719-406329-446754-174119
A25: SEB2021L | B25: 0024 | C25: 5CG1036C1H | D25: Bitlocker | E25: HP EliteBook 840 G7 | F25: JW | G25: Chupak Ak Insam | H25: Security | K25: Menara | L25: 29/03/2021 | M25: 44319 | N25: DT >> NB | O25: =_xlfn.XLOOKUP(G25,Sheet2!B:B,Sheet2!A:A,"",0,1) | P25: " | R25: FA2F220A-B69D-461D-8EB5-8F58ADDBC308 | S25: 016126-708092-158235-089727-489500-710281-182204-360745
A26: SEB2021L | B26: 0025 | C26: 5CG1036H4L | D26: Y | E26: HP EliteBook 840 G7 | F26: ULH | G26: Osman Bin Bujang Japar | H26: Distribution | K26: CR | L26: 44443 | M26: 44534 | O26: =_xlfn.XLOOKUP(G26,Sheet2!B:B,Sheet2!A:A,"",0,1) -> 44272 | P26: "
A27: SEB2021L | B27: 0026 | C27: 5CG1036BTP | D27: Bitlocker | E27: HP EliteBook 840 G7 | F27: Jacob | G27: BERA SIM | H27: BAKUN | K27: BAKUN | L27: 29/04/2021 | M27: 44291 | O27: =_xlfn.XLOOKUP(G27,Sheet2!B:B,Sheet2!A:A,"",0,1) -> 44273 | P27: " | R27: B925C4CF-1406-4C42-8E3C-8CCEE024DDEE | S27: 401203-541783-686609-056716-160380-509333-575245-639331
A28: SEB2021L | B28: 0027 | C28: 5CG1036BTT | D28: Bitlocker | E28: HP EliteBook 840 G7 | F28: Aziz | G28: Sandu Anak Julai | H28: GIS | K28: Sibu | L28: 21/04/2021 | M28: 21/04/2021 | N28: DT >> NB | O28: =_xlfn.XLOOKUP(G28,Sheet2!B:B,Sheet2!A:A,"",0,1) -> 44272 | P28: " | R28: 700889BA-8902-4601-92C6-2985361B820F | S28: 616209-352033-001815-093632-242583-527175-568953-037939
A29: SEB2021L | B29: 0028 | C29: 5CG1036GG3 | D29: Y | E29: HP EliteBook 840 G7 | F29: Jacob | G29: Moniliza Mujan Merang | H29: BAKUN | K29: Murum | L29: 29/04/2021 | M29: 04-May-2021 | O29: =_xlfn.XLOOKUP(G29,Sheet2!B:B,Sheet2!A:A,"",0,1) -> 44273 | P29: "
A30: SEB2021L | B30: 0029 | C30: 5CG1036GG0 | D30: y | E30: HP EliteBook 840 G7 | F30: Jacob | G30: JANE ERING | H30: BAKUN | K30: Murum | L30: 29/04/2021 | M30: 04-May-2021 | O30: =_xlfn.XLOOKUP(G30,Sheet2!B:B,Sheet2!A:A,"",0,1) -> 44273 | P30: "
A31: SEB2021L | B31: 0030 | C31: 5CG1036DDS | D31: Bitlocker | E31: HP EliteBook 840 G7 | F31: Yip | G31: CHUA SIEW YUN | K31: Kuching | L31: 24/03/2021 | M31: 26-March-2021 | N31: NB >> NB | P31: " | R31: F0913883-5B8A-47A5-BCE6-52D6626CDFF7 | S31: 283778-220781-497739-225709-251625-231693-600468-584958
A32: SEB2021L | B32: 0031 | C32: 5CG1036F4J | D32: Y | E32: HP EliteBook 840 G7 | F32: Aziz | G32: Pau Siu Yew | H32: Retail | K32: Sibu | L32: 15/04/2021 | M32: 17-Aug-2021 | N32: DT >> NB | O32: =_xlfn.XLOOKUP(G32,Sheet2!B:B,Sheet2!A:A,"",0,1) | P32: "
A33: SEB2021L | B33: 0032 | C33: 5CG1036DRX | D33: Bitlocker | E33: HP EliteBook 840 G7 | F33: ULH | G33: Tracy Anak Henry Mundu | H33: Distribution | K33: Sibu | L33: 21/04/2021 | M33: 21/04/2021 | N33: DT >> NB | O33: =_xlfn.XLOOKUP(G33,Sheet2!B:B,Sheet2!A:A,"",0,1) -> 44273 | P33: " | R33: 01E3C137-678A-4818-A2DF-E60525C51C29 | S33: 686983-462924-517462-510213-313203-712426-074129-238799
A34: SEB2021L | B34: 0033 | C34: 5CG1036DRP | D34: Bitlocker | E34: HP EliteBook 840 G7 | F34: Art | G34: Harold Anak Muhi | H34: Wayleave | K34: Menara | L34: 7-Apr-2021 | M34: 19-Apr-2021 | N34: DT >> NB | P34: "
A35: SEB2021L | B35: 0034 | C35: 5CG1036F43 | E35: HP EliteBook 840 G7 | F35: Adam | G35: Evelintina Edora Anak Sedempet | H35: Wayleave | K35: Menara | L35: 29-Mar-2021 | M35: 31-Mar-2021 | O35: =_xlfn.XLOOKUP(G35,Sheet2!B:B,Sheet2!A:A,"",0,1) | P35: "
A36: SEB2021L | B36: 0035 | C36: 5CG1036C9M | E36: HP EliteBook 840 G7 | G36: Terrence Blawan Ak Nuhip@Nyoging | K36: Menara | M36: 06-Sept-2021 | O36: =_xlfn.XLOOKUP(G36,Sheet2!B:B,Sheet2!A:A,"",0,1) | P36: "
A37: SEB2021L | B37: 0036 | C37: 5CG1036F49 | D37: Bitlocker | E37: HP EliteBook 840 G7 | G37: Anthony Leo Anak Akitson | K37: Menara | M37: 06-Sept-2021 | O37: =_xlfn.XLOOKUP(G37,Sheet2!B:B,Sheet2!A:A,"",0,1) | P37: " | R37: 59B1EB31-7F07-4BCE-A2C2-5828A35292AF | S37: 424545-235972-056870-029733-551056-627231-381601-174746
A38: SEB2021L | B38: 0037 | C38: 5CG1036C1G | E38: HP EliteBook 840 G7 | G38: Caleen Anak James Parot | K38: Menara | M38: 17-Aug-2021 | O38: =_xlfn.XLOOKUP(G38,Sheet2!B:B,Sheet2!A:A,"",0,1) | P38: "
A39: SEB2021L | B39: 0038 | C39: 5CG1036F4F | D39: Bitlocker | E39: HP EliteBook 840 G7 | F39: Art | G39: Quinnsay Anak Patrick | H39: Wayleave | K39: Menara | L39: 8-Apr-2021 | M39: 20-Apr-2021 | N39: DT >> NB | P39: "
A40: SEB2021L | B40: 0039 | C40: 5CG1036DSM | E40: HP EliteBook 840 G7 | F40: Yip | G40: Sabrina Rafaella | H40: Retail | K40: Wisma | L40: 25-Mar-2021 | M40: 25-Mar-2021 | O40: =_xlfn.XLOOKUP(G40,Sheet2!B:B,Sheet2!A:A,"",0,1) | P40: "
...
